<sdf version='1.6'>
  <world name='default'>
    <model name='ground_plane'>
      <static>1</static>
      <link name='link'>
        <collision name='collision'>
          <geometry>
            <plane>
              <normal>0 0 1</normal>
              <size>100 100</size>
            </plane>
          </geometry>
          <surface>
            <contact>
              <collide_bitmask>65535</collide_bitmask>
              <ode/>
            </contact>
            <friction>
              <ode>
                <mu>100</mu>
                <mu2>50</mu2>
              </ode>
              <torsional>
                <ode/>
              </torsional>
            </friction>
            <bounce/>
          </surface>
          <max_contacts>10</max_contacts>
        </collision>
        <visual name='visual'>
          <cast_shadows>0</cast_shadows>
          <geometry>
            <plane>
              <normal>0 0 1</normal>
              <size>100 100</size>
            </plane>
          </geometry>
          <material>
            <script>
              <uri>file://media/materials/scripts/gazebo.material</uri>
              <name>Gazebo/Grey</name>
            </script>
          </material>
        </visual>
        <self_collide>0</self_collide>
        <enable_wind>0</enable_wind>
        <kinematic>0</kinematic>
      </link>
    </model>
    <light name='sun' type='directional'>
      <cast_shadows>1</cast_shadows>
      <pose frame=''>0 0 10 0 -0 0</pose>
      <diffuse>0.8 0.8 0.8 1</diffuse>
      <specular>0.2 0.2 0.2 1</specular>
      <attenuation>
        <range>1000</range>
        <constant>0.9</constant>
        <linear>0.01</linear>
        <quadratic>0.001</quadratic>
      </attenuation>
      <direction>-0.5 0.1 -0.9</direction>
    </light>
    <model name='table'>
      <static>1</static>
      <link name='link'>
        <collision name='surface'>
          <pose frame=''>0 0 1 0 -0 0</pose>
          <geometry>
            <box>
              <size>1.5 0.8 0.03</size>
            </box>
          </geometry>
          <surface>
            <friction>
              <ode>
                <mu>0.6</mu>
                <mu2>0.6</mu2>
              </ode>
              <torsional>
                <ode/>
              </torsional>
            </friction>
            <contact>
              <ode/>
            </contact>
            <bounce/>
          </surface>
          <max_contacts>10</max_contacts>
        </collision>
        <visual name='visual1'>
          <pose frame=''>0 0 1 0 -0 0</pose>
          <geometry>
            <box>
              <size>1.5 0.8 0.03</size>
            </box>
          </geometry>
          <material>
            <script>
              <uri>file://media/materials/scripts/gazebo.material</uri>
              <name>Gazebo/Wood</name>
            </script>
          </material>
        </visual>
        <collision name='front_left_leg'>
          <pose frame=''>0.68 0.38 0.5 0 -0 0</pose>
          <geometry>
            <cylinder>
              <radius>0.02</radius>
              <length>1</length>
            </cylinder>
          </geometry>
          <max_contacts>10</max_contacts>
          <surface>
            <contact>
              <ode/>
            </contact>
            <bounce/>
            <friction>
              <torsional>
                <ode/>
              </torsional>
              <ode/>
            </friction>
          </surface>
        </collision>
        <visual name='front_left_leg'>
          <pose frame=''>0.68 0.38 0.5 0 -0 0</pose>
          <geometry>
            <cylinder>
              <radius>0.02</radius>
              <length>1</length>
            </cylinder>
          </geometry>
          <material>
            <script>
              <uri>file://media/materials/scripts/gazebo.material</uri>
              <name>Gazebo/Grey</name>
            </script>
          </material>
        </visual>
        <collision name='front_right_leg'>
          <pose frame=''>0.68 -0.38 0.5 0 -0 0</pose>
          <geometry>
            <cylinder>
              <radius>0.02</radius>
              <length>1</length>
            </cylinder>
          </geometry>
          <max_contacts>10</max_contacts>
          <surface>
            <contact>
              <ode/>
            </contact>
            <bounce/>
            <friction>
              <torsional>
                <ode/>
              </torsional>
              <ode/>
            </friction>
          </surface>
        </collision>
        <visual name='front_right_leg'>
          <pose frame=''>0.68 -0.38 0.5 0 -0 0</pose>
          <geometry>
            <cylinder>
              <radius>0.02</radius>
              <length>1</length>
            </cylinder>
          </geometry>
          <material>
            <script>
              <uri>file://media/materials/scripts/gazebo.material</uri>
              <name>Gazebo/Grey</name>
            </script>
          </material>
        </visual>
        <collision name='back_right_leg'>
          <pose frame=''>-0.68 -0.38 0.5 0 -0 0</pose>
          <geometry>
            <cylinder>
              <radius>0.02</radius>
              <length>1</length>
            </cylinder>
          </geometry>
          <max_contacts>10</max_contacts>
          <surface>
            <contact>
              <ode/>
            </contact>
            <bounce/>
            <friction>
              <torsional>
                <ode/>
              </torsional>
              <ode/>
            </friction>
          </surface>
        </collision>
        <visual name='back_right_leg'>
          <pose frame=''>-0.68 -0.38 0.5 0 -0 0</pose>
          <geometry>
            <cylinder>
              <radius>0.02</radius>
              <length>1</length>
            </cylinder>
          </geometry>
          <material>
            <script>
              <uri>file://media/materials/scripts/gazebo.material</uri>
              <name>Gazebo/Grey</name>
            </script>
          </material>
        </visual>
        <collision name='back_left_leg'>
          <pose frame=''>-0.68 0.38 0.5 0 -0 0</pose>
          <geometry>
            <cylinder>
              <radius>0.02</radius>
              <length>1</length>
            </cylinder>
          </geometry>
          <max_contacts>10</max_contacts>
          <surface>
            <contact>
              <ode/>
            </contact>
            <bounce/>
            <friction>
              <torsional>
                <ode/>
              </torsional>
              <ode/>
            </friction>
          </surface>
        </collision>
        <visual name='back_left_leg'>
          <pose frame=''>-0.68 0.38 0.5 0 -0 0</pose>
          <geometry>
            <cylinder>
              <radius>0.02</radius>
              <length>1</length>
            </cylinder>
          </geometry>
          <material>
            <script>
              <uri>file://media/materials/scripts/gazebo.material</uri>
              <name>Gazebo/Grey</name>
            </script>
          </material>
        </visual>
        <self_collide>0</self_collide>
        <enable_wind>0</enable_wind>
        <kinematic>0</kinematic>
      </link>
      <pose frame=''>0 -0.84 0 0 -0 0</pose>
    </model>
    <physics name='default_physics' default='0' type='ode'>
      <max_step_size>0.001</max_step_size>
      <real_time_factor>1</real_time_factor>
      <real_time_update_rate>1000</real_time_update_rate>
    </physics>
    <gravity>0 0 -9.81</gravity>
    <magnetic_field>6e-06 2.3e-05 -4.2e-05</magnetic_field>
    <atmosphere type='adiabatic'/>
    <scene>
      <ambient>0.4 0.4 0.4 1</ambient>
      <background>0.7 0.7 0.7 1</background>
      <shadows>1</shadows>
    </scene>
    <audio>
      <device>default</device>
    </audio>
    <wind/>
    <spherical_coordinates>
      <surface_model>EARTH_WGS84</surface_model>
      <latitude_deg>0</latitude_deg>
      <longitude_deg>0</longitude_deg>
      <elevation>0</elevation>
      <heading_deg>0</heading_deg>
    </spherical_coordinates>
    <model name='xarm7'>
      <link name='link_base'>
        <pose frame=''>0 0 0 0 -0 0</pose>
        <inertial>
          <pose frame=''>-0.021131 -0.00163 0.056488 0 -0 0</pose>
          <mass>0.88556</mass>
          <inertia>
            <ixx>0.0030595</ixx>
            <ixy>0.00012259</ixy>
            <ixz>-0.00062705</ixz>
            <iyy>0.0037783</iyy>
            <iyz>0.00027023</iyz>
            <izz>0.0020125</izz>
          </inertia>
        </inertial>
        <collision name='link_base_collision'>
          <pose frame=''>0 0 0 0 -0 0</pose>
          <geometry>
            <mesh>
              <scale>1 1 1</scale>
              <uri>/home/mcr2/Desktop/gitManCourseFeb2022/ManipulatorsFeb2022/test_arm/src/xarm_ros/xarm_description/meshes/xarm7/visual/link_base.STL</uri>
            </mesh>
          </geometry>
          <surface>
            <contact>
              <ode/>
            </contact>
            <friction>
              <ode/>
              <torsional>
                <ode/>
              </torsional>
            </friction>
            <bounce/>
          </surface>
          <max_contacts>10</max_contacts>
        </collision>
        <visual name='link_base_visual'>
          <pose frame=''>0 0 0 0 -0 0</pose>
          <geometry>
            <mesh>
              <scale>1 1 1</scale>
              <uri>/home/mcr2/Desktop/gitManCourseFeb2022/ManipulatorsFeb2022/test_arm/src/xarm_ros/xarm_description/meshes/xarm7/visual/link_base.STL</uri>
            </mesh>
          </geometry>
          <material>
            <script>
              <uri>__default__</uri>
              <name>__default__</name>
            </script>
          </material>
        </visual>
        <gravity>1</gravity>
        <velocity_decay/>
        <self_collide>1</self_collide>
        <enable_wind>0</enable_wind>
        <kinematic>0</kinematic>
      </link>
      <joint name='world_joint' type='fixed'>
        <child>link_base</child>
        <parent>world</parent>
      </joint>
      <link name='link1'>
        <pose frame=''>0 0 0.267 0 -0 0</pose>
        <inertial>
          <pose frame=''>-0.004214 0.02821 -0.008779 0 -0 0</pose>
          <mass>0.42603</mass>
          <inertia>
            <ixx>0.0014243</ixx>
            <ixy>3.9946e-05</ixy>
            <ixz>4.7078e-06</ixz>
            <iyy>0.00123</iyy>
            <iyz>-0.00026073</iyz>
            <izz>0.00099229</izz>
          </inertia>
        </inertial>
        <collision name='link1_collision'>
          <pose frame=''>0 0 0 0 -0 0</pose>
          <geometry>
            <mesh>
              <scale>1 1 1</scale>
              <uri>/home/mcr2/Desktop/gitManCourseFeb2022/ManipulatorsFeb2022/test_arm/src/xarm_ros/xarm_description/meshes/xarm7/visual/link1.STL</uri>
            </mesh>
          </geometry>
          <surface>
            <contact>
              <ode/>
            </contact>
            <friction>
              <ode/>
              <torsional>
                <ode/>
              </torsional>
            </friction>
            <bounce/>
          </surface>
          <max_contacts>10</max_contacts>
        </collision>
        <visual name='link1_visual'>
          <pose frame=''>0 0 0 0 -0 0</pose>
          <geometry>
            <mesh>
              <scale>1 1 1</scale>
              <uri>/home/mcr2/Desktop/gitManCourseFeb2022/ManipulatorsFeb2022/test_arm/src/xarm_ros/xarm_description/meshes/xarm7/visual/link1.STL</uri>
            </mesh>
          </geometry>
          <material>
            <script>
              <uri>__default__</uri>
              <name>__default__</name>
            </script>
          </material>
        </visual>
        <gravity>1</gravity>
        <velocity_decay/>
        <self_collide>1</self_collide>
        <enable_wind>0</enable_wind>
        <kinematic>0</kinematic>
      </link>
      <joint name='joint1' type='revolute'>
        <child>link1</child>
        <parent>link_base</parent>
        <axis>
          <xyz>0 0 1</xyz>
          <limit>
            <lower>-6.28319</lower>
            <upper>6.28319</upper>
            <effort>50</effort>
            <velocity>3.14</velocity>
          </limit>
          <dynamics>
            <damping>10</damping>
            <friction>1</friction>
            <spring_reference>0</spring_reference>
            <spring_stiffness>0</spring_stiffness>
          </dynamics>
          <use_parent_model_frame>1</use_parent_model_frame>
        </axis>
      </joint>
      <link name='link2'>
        <pose frame=''>0 0 0.267 -1.5708 0 0</pose>
        <inertial>
          <pose frame=''>-3.3e-05 -0.12849 0.026337 0 -0 0</pose>
          <mass>0.56095</mass>
          <inertia>
            <ixx>0.0031915</ixx>
            <ixy>3.0892e-06</ixy>
            <ixz>2.8729e-06</ixz>
            <iyy>0.0017468</iyy>
            <iyz>-0.0010241</iyz>
            <izz>0.00235</izz>
          </inertia>
        </inertial>
        <collision name='link2_collision'>
          <pose frame=''>0 0 0 0 -0 0</pose>
          <geometry>
            <mesh>
              <scale>1 1 1</scale>
              <uri>/home/mcr2/Desktop/gitManCourseFeb2022/ManipulatorsFeb2022/test_arm/src/xarm_ros/xarm_description/meshes/xarm7/visual/link2.STL</uri>
            </mesh>
          </geometry>
          <surface>
            <contact>
              <ode/>
            </contact>
            <friction>
              <ode/>
              <torsional>
                <ode/>
              </torsional>
            </friction>
            <bounce/>
          </surface>
          <max_contacts>10</max_contacts>
        </collision>
        <visual name='link2_visual'>
          <pose frame=''>0 0 0 0 -0 0</pose>
          <geometry>
            <mesh>
              <scale>1 1 1</scale>
              <uri>/home/mcr2/Desktop/gitManCourseFeb2022/ManipulatorsFeb2022/test_arm/src/xarm_ros/xarm_description/meshes/xarm7/visual/link2.STL</uri>
            </mesh>
          </geometry>
          <material>
            <script>
              <uri>__default__</uri>
              <name>__default__</name>
            </script>
          </material>
        </visual>
        <gravity>1</gravity>
        <velocity_decay/>
        <self_collide>1</self_collide>
        <enable_wind>0</enable_wind>
        <kinematic>0</kinematic>
      </link>
      <joint name='joint2' type='revolute'>
        <child>link2</child>
        <parent>link1</parent>
        <axis>
          <xyz>0 1 -4e-06</xyz>
          <limit>
            <lower>-2.059</lower>
            <upper>2.0944</upper>
            <effort>50</effort>
            <velocity>3.14</velocity>
          </limit>
          <dynamics>
            <damping>10</damping>
            <friction>1</friction>
            <spring_reference>0</spring_reference>
            <spring_stiffness>0</spring_stiffness>
          </dynamics>
          <use_parent_model_frame>1</use_parent_model_frame>
        </axis>
      </joint>
      <link name='link3'>
        <pose frame=''>0 1e-06 0.56 0 -0 0</pose>
        <inertial>
          <pose frame=''>0.04223 -0.023258 -0.009667 0 -0 0</pose>
          <mass>0.44463</mass>
          <inertia>
            <ixx>0.0011454</ixx>
            <ixy>0.0001654</ixy>
            <ixz>-0.0001951</ixz>
            <iyy>0.0010503</iyy>
            <iyz>0.00012027</iyz>
            <izz>0.0011083</izz>
          </inertia>
        </inertial>
        <collision name='link3_collision'>
          <pose frame=''>0 0 0 0 -0 0</pose>
          <geometry>
            <mesh>
              <scale>1 1 1</scale>
              <uri>/home/mcr2/Desktop/gitManCourseFeb2022/ManipulatorsFeb2022/test_arm/src/xarm_ros/xarm_description/meshes/xarm7/visual/link3.STL</uri>
            </mesh>
          </geometry>
          <surface>
            <contact>
              <ode/>
            </contact>
            <friction>
              <ode/>
              <torsional>
                <ode/>
              </torsional>
            </friction>
            <bounce/>
          </surface>
          <max_contacts>10</max_contacts>
        </collision>
        <visual name='link3_visual'>
          <pose frame=''>0 0 0 0 -0 0</pose>
          <geometry>
            <mesh>
              <scale>1 1 1</scale>
              <uri>/home/mcr2/Desktop/gitManCourseFeb2022/ManipulatorsFeb2022/test_arm/src/xarm_ros/xarm_description/meshes/xarm7/visual/link3.STL</uri>
            </mesh>
          </geometry>
          <material>
            <script>
              <uri>__default__</uri>
              <name>__default__</name>
            </script>
          </material>
        </visual>
        <gravity>1</gravity>
        <velocity_decay/>
        <self_collide>1</self_collide>
        <enable_wind>0</enable_wind>
        <kinematic>0</kinematic>
      </link>
      <joint name='joint3' type='revolute'>
        <child>link3</child>
        <parent>link2</parent>
        <axis>
          <xyz>0 0 1</xyz>
          <limit>
            <lower>-6.28319</lower>
            <upper>6.28319</upper>
            <effort>30</effort>
            <velocity>3.14</velocity>
          </limit>
          <dynamics>
            <damping>5</damping>
            <friction>1</friction>
            <spring_reference>0</spring_reference>
            <spring_stiffness>0</spring_stiffness>
          </dynamics>
          <use_parent_model_frame>1</use_parent_model_frame>
        </axis>
      </joint>
      <link name='link4'>
        <pose frame=''>0.0525 1e-06 0.56 1.5708 -0 0</pose>
        <inertial>
          <pose frame=''>0.067148 -0.10732 0.024479 0 -0 0</pose>
          <mass>0.52387</mass>
          <inertia>
            <ixx>0.0026033</ixx>
            <ixy>0.00053379</ixy>
            <ixz>0.00036314</ixz>
            <iyy>0.0017649</iyy>
            <iyz>-0.00083253</iyz>
            <izz>0.0022431</izz>
          </inertia>
        </inertial>
        <collision name='link4_collision'>
          <pose frame=''>0 0 0 0 -0 0</pose>
          <geometry>
            <mesh>
              <scale>1 1 1</scale>
              <uri>/home/mcr2/Desktop/gitManCourseFeb2022/ManipulatorsFeb2022/test_arm/src/xarm_ros/xarm_description/meshes/xarm7/visual/link4.STL</uri>
            </mesh>
          </geometry>
          <surface>
            <contact>
              <ode/>
            </contact>
            <friction>
              <ode/>
              <torsional>
                <ode/>
              </torsional>
            </friction>
            <bounce/>
          </surface>
          <max_contacts>10</max_contacts>
        </collision>
        <visual name='link4_visual'>
          <pose frame=''>0 0 0 0 -0 0</pose>
          <geometry>
            <mesh>
              <scale>1 1 1</scale>
              <uri>/home/mcr2/Desktop/gitManCourseFeb2022/ManipulatorsFeb2022/test_arm/src/xarm_ros/xarm_description/meshes/xarm7/visual/link4.STL</uri>
            </mesh>
          </geometry>
          <material>
            <script>
              <uri>__default__</uri>
              <name>__default__</name>
            </script>
          </material>
        </visual>
        <gravity>1</gravity>
        <velocity_decay/>
        <self_collide>1</self_collide>
        <enable_wind>0</enable_wind>
        <kinematic>0</kinematic>
      </link>
      <joint name='joint4' type='revolute'>
        <child>link4</child>
        <parent>link3</parent>
        <axis>
          <xyz>0 -1 -4e-06</xyz>
          <limit>
            <lower>-0.19198</lower>
            <upper>3.927</upper>
            <effort>30</effort>
            <velocity>3.14</velocity>
          </limit>
          <dynamics>
            <damping>5</damping>
            <friction>1</friction>
            <spring_reference>0</spring_reference>
            <spring_stiffness>0</spring_stiffness>
          </dynamics>
          <use_parent_model_frame>1</use_parent_model_frame>
        </axis>
      </joint>
      <link name='link5'>
        <pose frame=''>0.13 2e-06 0.2175 -3.14159 -0 0</pose>
        <inertial>
          <pose frame=''>-0.000234 0.036705 -0.080064 0 -0 0</pose>
          <mass>0.18554</mass>
          <inertia>
            <ixx>0.00099549</ixx>
            <ixy>8.9957e-07</ixy>
            <ixz>8.5285e-07</ixz>
            <iyy>0.0008853</iyy>
            <iyz>-0.00025682</iyz>
            <izz>0.00035048</izz>
          </inertia>
        </inertial>
        <collision name='link5_collision'>
          <pose frame=''>0 0 0 0 -0 0</pose>
          <geometry>
            <mesh>
              <scale>1 1 1</scale>
              <uri>/home/mcr2/Desktop/gitManCourseFeb2022/ManipulatorsFeb2022/test_arm/src/xarm_ros/xarm_description/meshes/xarm7/visual/link5.STL</uri>
            </mesh>
          </geometry>
          <surface>
            <contact>
              <ode/>
            </contact>
            <friction>
              <ode/>
              <torsional>
                <ode/>
              </torsional>
            </friction>
            <bounce/>
          </surface>
          <max_contacts>10</max_contacts>
        </collision>
        <visual name='link5_visual'>
          <pose frame=''>0 0 0 0 -0 0</pose>
          <geometry>
            <mesh>
              <scale>1 1 1</scale>
              <uri>/home/mcr2/Desktop/gitManCourseFeb2022/ManipulatorsFeb2022/test_arm/src/xarm_ros/xarm_description/meshes/xarm7/visual/link5.STL</uri>
            </mesh>
          </geometry>
          <material>
            <script>
              <uri>__default__</uri>
              <name>__default__</name>
            </script>
          </material>
        </visual>
        <gravity>1</gravity>
        <velocity_decay/>
        <self_collide>1</self_collide>
        <enable_wind>0</enable_wind>
        <kinematic>0</kinematic>
      </link>
      <joint name='joint5' type='revolute'>
        <child>link5</child>
        <parent>link4</parent>
        <axis>
          <xyz>0 7e-06 -1</xyz>
          <limit>
            <lower>-6.28319</lower>
            <upper>6.28319</upper>
            <effort>30</effort>
            <velocity>3.14</velocity>
          </limit>
          <dynamics>
            <damping>5</damping>
            <friction>1</friction>
            <spring_reference>0</spring_reference>
            <spring_stiffness>0</spring_stiffness>
          </dynamics>
          <use_parent_model_frame>1</use_parent_model_frame>
        </axis>
      </joint>
      <link name='link6'>
        <pose frame=''>0.13 2e-06 0.2175 -1.57079 -0 0</pose>
        <inertial>
          <pose frame=''>0.058911 0.028469 0.006843 0 -0 0</pose>
          <mass>0.31344</mass>
          <inertia>
            <ixx>0.00052034</ixx>
            <ixy>-0.00014989</ixy>
            <ixz>0.00011658</ixz>
            <iyy>0.00067968</iyy>
            <iyz>6.116e-05</iyz>
            <izz>0.00078345</izz>
          </inertia>
        </inertial>
        <collision name='link6_collision'>
          <pose frame=''>0 0 0 0 -0 0</pose>
          <geometry>
            <mesh>
              <scale>1 1 1</scale>
              <uri>/home/mcr2/Desktop/gitManCourseFeb2022/ManipulatorsFeb2022/test_arm/src/xarm_ros/xarm_description/meshes/xarm7/visual/link6.STL</uri>
            </mesh>
          </geometry>
          <surface>
            <contact>
              <ode/>
            </contact>
            <friction>
              <ode/>
              <torsional>
                <ode/>
              </torsional>
            </friction>
            <bounce/>
          </surface>
          <max_contacts>10</max_contacts>
        </collision>
        <visual name='link6_visual'>
          <pose frame=''>0 0 0 0 -0 0</pose>
          <geometry>
            <mesh>
              <scale>1 1 1</scale>
              <uri>/home/mcr2/Desktop/gitManCourseFeb2022/ManipulatorsFeb2022/test_arm/src/xarm_ros/xarm_description/meshes/xarm7/visual/link6.STL</uri>
            </mesh>
          </geometry>
          <material>
            <script>
              <uri>__default__</uri>
              <name>__default__</name>
            </script>
          </material>
        </visual>
        <gravity>1</gravity>
        <velocity_decay/>
        <self_collide>1</self_collide>
        <enable_wind>0</enable_wind>
        <kinematic>0</kinematic>
      </link>
      <joint name='joint6' type='revolute'>
        <child>link6</child>
        <parent>link5</parent>
        <axis>
          <xyz>0 1 1.1e-05</xyz>
          <limit>
            <lower>-1.69297</lower>
            <upper>3.14159</upper>
            <effort>20</effort>
            <velocity>3.14</velocity>
          </limit>
          <dynamics>
            <damping>2</damping>
            <friction>1</friction>
            <spring_reference>0</spring_reference>
            <spring_stiffness>0</spring_stiffness>
          </dynamics>
          <use_parent_model_frame>1</use_parent_model_frame>
        </axis>
      </joint>
      <link name='link7'>
        <pose frame=''>0.206 3e-06 0.1205 -3.14159 -0 0</pose>
        <inertial>
          <pose frame=''>-0.00042 -0.002874 0.025708 0 -0 0</pose>
          <mass>0.85624</mass>
          <inertia>
            <ixx>0.00137658</ixx>
            <ixy>8.58544e-07</ixy>
            <ixz>1.04294e-05</ixz>
            <iyy>0.00118417</iyy>
            <iyz>-4.68007e-05</iyz>
            <izz>0.000518368</izz>
          </inertia>
        </inertial>
        <collision name='link7_collision'>
          <pose frame=''>0 0 0 0 -0 0</pose>
          <geometry>
            <mesh>
              <scale>1 1 1</scale>
              <uri>/home/mcr2/Desktop/gitManCourseFeb2022/ManipulatorsFeb2022/test_arm/src/xarm_ros/xarm_description/meshes/collision/end_tool.STL</uri>
            </mesh>
          </geometry>
          <surface>
            <contact>
              <ode/>
            </contact>
            <friction>
              <ode/>
              <torsional>
                <ode/>
              </torsional>
            </friction>
            <bounce/>
          </surface>
          <max_contacts>10</max_contacts>
        </collision>
        <collision name='link7_fixed_joint_lump__xarm_gripper_base_link_collision_1'>
          <pose frame=''>0 0 0 0 -0 0</pose>
          <geometry>
            <mesh>
              <scale>1 1 1</scale>
              <uri>/home/mcr2/Desktop/gitManCourseFeb2022/ManipulatorsFeb2022/test_arm/src/xarm_ros/xarm_gripper/meshes/base_link_collision.STL</uri>
            </mesh>
          </geometry>
          <surface>
            <contact>
              <ode/>
            </contact>
            <friction>
              <ode/>
              <torsional>
                <ode/>
              </torsional>
            </friction>
            <bounce/>
          </surface>
          <max_contacts>10</max_contacts>
        </collision>
        <visual name='link7_visual'>
          <pose frame=''>0 0 0 0 -0 0</pose>
          <geometry>
            <mesh>
              <scale>1 1 1</scale>
              <uri>/home/mcr2/Desktop/gitManCourseFeb2022/ManipulatorsFeb2022/test_arm/src/xarm_ros/xarm_description/meshes/xarm7/visual/link7.STL</uri>
            </mesh>
          </geometry>
          <material>
            <script>
              <uri>__default__</uri>
              <name>__default__</name>
            </script>
          </material>
        </visual>
        <visual name='link7_fixed_joint_lump__xarm_gripper_base_link_visual_1'>
          <pose frame=''>0 0 0 0 -0 0</pose>
          <geometry>
            <mesh>
              <scale>1 1 1</scale>
              <uri>/home/mcr2/Desktop/gitManCourseFeb2022/ManipulatorsFeb2022/test_arm/src/xarm_ros/xarm_gripper/meshes/base_link.STL</uri>
            </mesh>
          </geometry>
          <material>
            <script>
              <uri>__default__</uri>
              <name>__default__</name>
            </script>
          </material>
        </visual>
        <velocity_decay/>
        <gravity>1</gravity>
        <velocity_decay/>
        <self_collide>0</self_collide>
        <enable_wind>0</enable_wind>
        <kinematic>0</kinematic>
      </link>
      <joint name='joint7' type='revolute'>
        <child>link7</child>
        <parent>link6</parent>
        <axis>
          <xyz>0 7e-06 -1</xyz>
          <limit>
            <lower>-6.28319</lower>
            <upper>6.28319</upper>
            <effort>20</effort>
            <velocity>3.14</velocity>
          </limit>
          <dynamics>
            <damping>2</damping>
            <friction>1</friction>
            <spring_reference>0</spring_reference>
            <spring_stiffness>0</spring_stiffness>
          </dynamics>
          <use_parent_model_frame>1</use_parent_model_frame>
        </axis>
      </joint>
      <link name='left_outer_knuckle'>
        <pose frame=''>0.206 -0.034996 0.061402 -3.14159 -0 0</pose>
        <inertial>
          <pose frame=''>0 0.021559 0.015181 0 -0 0</pose>
          <mass>0.033618</mass>
          <inertia>
            <ixx>1.9111e-05</ixx>
            <ixy>-1.8803e-17</ixy>
            <ixz>-1.1002e-17</ixz>
            <iyy>6.6256e-06</iyy>
            <iyz>-7.3008e-06</iyz>
            <izz>1.3185e-05</izz>
          </inertia>
        </inertial>
        <collision name='left_outer_knuckle_collision'>
          <pose frame=''>0 0 0 0 -0 0</pose>
          <geometry>
            <mesh>
              <scale>1 1 1</scale>
              <uri>/home/mcr2/Desktop/gitManCourseFeb2022/ManipulatorsFeb2022/test_arm/src/xarm_ros/xarm_gripper/meshes/left_outer_knuckle.STL</uri>
            </mesh>
          </geometry>
          <surface>
            <contact>
              <ode/>
            </contact>
            <friction>
              <ode/>
              <torsional>
                <ode/>
              </torsional>
            </friction>
            <bounce/>
          </surface>
          <max_contacts>10</max_contacts>
        </collision>
        <visual name='left_outer_knuckle_visual'>
          <pose frame=''>0 0 0 0 -0 0</pose>
          <geometry>
            <mesh>
              <scale>1 1 1</scale>
              <uri>/home/mcr2/Desktop/gitManCourseFeb2022/ManipulatorsFeb2022/test_arm/src/xarm_ros/xarm_gripper/meshes/left_outer_knuckle.STL</uri>
            </mesh>
          </geometry>
          <material>
            <script>
              <uri>__default__</uri>
              <name>__default__</name>
            </script>
          </material>
        </visual>
        <gravity>1</gravity>
        <velocity_decay/>
        <self_collide>0</self_collide>
        <enable_wind>0</enable_wind>
        <kinematic>0</kinematic>
      </link>
      <joint name='drive_joint' type='revolute'>
        <child>left_outer_knuckle</child>
        <parent>link7</parent>
        <axis>
          <xyz>1 0 0</xyz>
          <limit>
            <lower>0</lower>
            <upper>0.85</upper>
            <effort>50</effort>
            <velocity>2</velocity>
          </limit>
          <dynamics>
            <spring_reference>0</spring_reference>
            <spring_stiffness>0</spring_stiffness>
          </dynamics>
          <use_parent_model_frame>1</use_parent_model_frame>
        </axis>
      </joint>
      <link name='left_finger'>
        <pose frame=''>0.206 -0.070461 0.019363 -3.14159 -0 0</pose>
        <inertial>
          <pose frame=''>-0 -0.016413 0.029258 0 -0 0</pose>
          <mass>0.048304</mass>
          <inertia>
            <ixx>1.7493e-05</ixx>
            <ixy>-4.2156e-19</ixy>
            <ixz>6.9164e-18</ixz>
            <iyy>1.7225e-05</iyy>
            <iyz>4.6433e-06</iyz>
            <izz>5.1466e-06</izz>
          </inertia>
        </inertial>
        <collision name='left_finger_collision'>
          <pose frame=''>0 0 0 0 -0 0</pose>
          <geometry>
            <mesh>
              <scale>1 1 1</scale>
              <uri>/home/mcr2/Desktop/gitManCourseFeb2022/ManipulatorsFeb2022/test_arm/src/xarm_ros/xarm_gripper/meshes/left_finger.STL</uri>
            </mesh>
          </geometry>
          <surface>
            <contact>
              <ode/>
            </contact>
            <friction>
              <ode/>
              <torsional>
                <ode/>
              </torsional>
            </friction>
            <bounce/>
          </surface>
          <max_contacts>10</max_contacts>
        </collision>
        <visual name='left_finger_visual'>
          <pose frame=''>0 0 0 0 -0 0</pose>
          <geometry>
            <mesh>
              <scale>1 1 1</scale>
              <uri>/home/mcr2/Desktop/gitManCourseFeb2022/ManipulatorsFeb2022/test_arm/src/xarm_ros/xarm_gripper/meshes/left_finger.STL</uri>
            </mesh>
          </geometry>
          <material>
            <script>
              <uri>__default__</uri>
              <name>__default__</name>
            </script>
          </material>
        </visual>
        <gravity>1</gravity>
        <velocity_decay/>
        <self_collide>0</self_collide>
        <enable_wind>0</enable_wind>
        <kinematic>0</kinematic>
      </link>
      <joint name='left_finger_joint' type='revolute'>
        <child>left_finger</child>
        <parent>left_outer_knuckle</parent>
        <axis>
          <xyz>-1 0 -0</xyz>
          <limit>
            <lower>0</lower>
            <upper>0.85</upper>
            <effort>50</effort>
            <velocity>2</velocity>
          </limit>
          <dynamics>
            <spring_reference>0</spring_reference>
            <spring_stiffness>0</spring_stiffness>
          </dynamics>
          <use_parent_model_frame>1</use_parent_model_frame>
        </axis>
      </joint>
      <link name='left_inner_knuckle'>
        <pose frame=''>0.206 -0.019996 0.046402 -3.14159 -0 0</pose>
        <inertial>
          <pose frame=''>2e-06 0.022047 0.026134 0 -0 0</pose>
          <mass>0.0230126</mass>
          <inertia>
            <ixx>6.0949e-06</ixx>
            <ixy>6.06651e-11</ixy>
            <ixz>7.19103e-11</ixz>
            <iyy>6.01955e-06</iyy>
            <iyz>-2.75317e-06</iyz>
            <izz>5.07862e-06</izz>
          </inertia>
        </inertial>
        <collision name='left_inner_knuckle_collision'>
          <pose frame=''>0 0 0 0 -0 0</pose>
          <geometry>
            <mesh>
              <scale>1 1 1</scale>
              <uri>/home/mcr2/Desktop/gitManCourseFeb2022/ManipulatorsFeb2022/test_arm/src/xarm_ros/xarm_gripper/meshes/left_inner_knuckle.STL</uri>
            </mesh>
          </geometry>
          <surface>
            <contact>
              <ode/>
            </contact>
            <friction>
              <ode/>
              <torsional>
                <ode/>
              </torsional>
            </friction>
            <bounce/>
          </surface>
          <max_contacts>10</max_contacts>
        </collision>
        <visual name='left_inner_knuckle_visual'>
          <pose frame=''>0 0 0 0 -0 0</pose>
          <geometry>
            <mesh>
              <scale>1 1 1</scale>
              <uri>/home/mcr2/Desktop/gitManCourseFeb2022/ManipulatorsFeb2022/test_arm/src/xarm_ros/xarm_gripper/meshes/left_inner_knuckle.STL</uri>
            </mesh>
          </geometry>
          <material>
            <script>
              <uri>__default__</uri>
              <name>__default__</name>
            </script>
          </material>
        </visual>
        <gravity>1</gravity>
        <velocity_decay/>
        <self_collide>0</self_collide>
        <enable_wind>0</enable_wind>
        <kinematic>0</kinematic>
      </link>
      <joint name='left_inner_knuckle_joint' type='revolute'>
        <child>left_inner_knuckle</child>
        <parent>link7</parent>
        <axis>
          <xyz>1 0 0</xyz>
          <limit>
            <lower>0</lower>
            <upper>0.85</upper>
            <effort>50</effort>
            <velocity>2</velocity>
          </limit>
          <dynamics>
            <spring_reference>0</spring_reference>
            <spring_stiffness>0</spring_stiffness>
          </dynamics>
          <use_parent_model_frame>1</use_parent_model_frame>
        </axis>
      </joint>
      <link name='right_inner_knuckle'>
        <pose frame=''>0.206 0.020004 0.046402 -3.14159 -0 0</pose>
        <inertial>
          <pose frame=''>2e-06 -0.022047 0.026133 0 -0 0</pose>
          <mass>0.023013</mass>
          <inertia>
            <ixx>6.0949e-06</ixx>
            <ixy>-6.0665e-11</ixy>
            <ixz>7.191e-11</ixz>
            <iyy>6.0197e-06</iyy>
            <iyz>2.7531e-06</iyz>
            <izz>5.0784e-06</izz>
          </inertia>
        </inertial>
        <collision name='right_inner_knuckle_collision'>
          <pose frame=''>0 0 0 0 -0 0</pose>
          <geometry>
            <mesh>
              <scale>1 1 1</scale>
              <uri>/home/mcr2/Desktop/gitManCourseFeb2022/ManipulatorsFeb2022/test_arm/src/xarm_ros/xarm_gripper/meshes/right_inner_knuckle.STL</uri>
            </mesh>
          </geometry>
          <surface>
            <contact>
              <ode/>
            </contact>
            <friction>
              <ode/>
              <torsional>
                <ode/>
              </torsional>
            </friction>
            <bounce/>
          </surface>
          <max_contacts>10</max_contacts>
        </collision>
        <visual name='right_inner_knuckle_visual'>
          <pose frame=''>0 0 0 0 -0 0</pose>
          <geometry>
            <mesh>
              <scale>1 1 1</scale>
              <uri>/home/mcr2/Desktop/gitManCourseFeb2022/ManipulatorsFeb2022/test_arm/src/xarm_ros/xarm_gripper/meshes/right_inner_knuckle.STL</uri>
            </mesh>
          </geometry>
          <material>
            <script>
              <uri>__default__</uri>
              <name>__default__</name>
            </script>
          </material>
        </visual>
        <gravity>1</gravity>
        <velocity_decay/>
        <self_collide>0</self_collide>
        <enable_wind>0</enable_wind>
        <kinematic>0</kinematic>
      </link>
      <joint name='right_inner_knuckle_joint' type='revolute'>
        <child>right_inner_knuckle</child>
        <parent>link7</parent>
        <axis>
          <xyz>-1 0 -0</xyz>
          <limit>
            <lower>0</lower>
            <upper>0.85</upper>
            <effort>50</effort>
            <velocity>2</velocity>
          </limit>
          <dynamics>
            <spring_reference>0</spring_reference>
            <spring_stiffness>0</spring_stiffness>
          </dynamics>
          <use_parent_model_frame>1</use_parent_model_frame>
        </axis>
      </joint>
      <link name='right_outer_knuckle'>
        <pose frame=''>0.206 0.035004 0.061402 -3.14159 -0 0</pose>
        <inertial>
          <pose frame=''>-0 -0.021559 0.015181 0 -0 0</pose>
          <mass>0.033618</mass>
          <inertia>
            <ixx>1.9111e-05</ixx>
            <ixy>-1.8789e-17</ixy>
            <ixz>1.0986e-17</ixz>
            <iyy>6.6256e-06</iyy>
            <iyz>7.3008e-06</iyz>
            <izz>1.3185e-05</izz>
          </inertia>
        </inertial>
        <collision name='right_outer_knuckle_collision'>
          <pose frame=''>0 0 0 0 -0 0</pose>
          <geometry>
            <mesh>
              <scale>1 1 1</scale>
              <uri>/home/mcr2/Desktop/gitManCourseFeb2022/ManipulatorsFeb2022/test_arm/src/xarm_ros/xarm_gripper/meshes/right_outer_knuckle.STL</uri>
            </mesh>
          </geometry>
          <surface>
            <contact>
              <ode/>
            </contact>
            <friction>
              <ode/>
              <torsional>
                <ode/>
              </torsional>
            </friction>
            <bounce/>
          </surface>
          <max_contacts>10</max_contacts>
        </collision>
        <visual name='right_outer_knuckle_visual'>
          <pose frame=''>0 0 0 0 -0 0</pose>
          <geometry>
            <mesh>
              <scale>1 1 1</scale>
              <uri>/home/mcr2/Desktop/gitManCourseFeb2022/ManipulatorsFeb2022/test_arm/src/xarm_ros/xarm_gripper/meshes/right_outer_knuckle.STL</uri>
            </mesh>
          </geometry>
          <material>
            <script>
              <uri>__default__</uri>
              <name>__default__</name>
            </script>
          </material>
        </visual>
        <gravity>1</gravity>
        <velocity_decay/>
        <self_collide>0</self_collide>
        <enable_wind>0</enable_wind>
        <kinematic>0</kinematic>
      </link>
      <joint name='right_outer_knuckle_joint' type='revolute'>
        <child>right_outer_knuckle</child>
        <parent>link7</parent>
        <axis>
          <xyz>-1 0 -0</xyz>
          <limit>
            <lower>0</lower>
            <upper>0.85</upper>
            <effort>50</effort>
            <velocity>2</velocity>
          </limit>
          <dynamics>
            <spring_reference>0</spring_reference>
            <spring_stiffness>0</spring_stiffness>
          </dynamics>
          <use_parent_model_frame>1</use_parent_model_frame>
        </axis>
      </joint>
      <link name='right_finger'>
        <pose frame=''>0.206 0.070469 0.019364 -3.14159 -0 0</pose>
        <inertial>
          <pose frame=''>0 0.016413 0.029258 0 -0 0</pose>
          <mass>0.048304</mass>
          <inertia>
            <ixx>1.7493e-05</ixx>
            <ixy>-5.0014e-19</ixy>
            <ixz>-7.5079e-18</ixz>
            <iyy>1.7225e-05</iyy>
            <iyz>-4.6435e-06</iyz>
            <izz>5.1466e-06</izz>
          </inertia>
        </inertial>
        <collision name='right_finger_collision'>
          <pose frame=''>0 0 0 0 -0 0</pose>
          <geometry>
            <mesh>
              <scale>1 1 1</scale>
              <uri>/home/mcr2/Desktop/gitManCourseFeb2022/ManipulatorsFeb2022/test_arm/src/xarm_ros/xarm_gripper/meshes/right_finger.STL</uri>
            </mesh>
          </geometry>
          <surface>
            <contact>
              <ode/>
            </contact>
            <friction>
              <ode/>
              <torsional>
                <ode/>
              </torsional>
            </friction>
            <bounce/>
          </surface>
          <max_contacts>10</max_contacts>
        </collision>
        <visual name='right_finger_visual'>
          <pose frame=''>0 0 0 0 -0 0</pose>
          <geometry>
            <mesh>
              <scale>1 1 1</scale>
              <uri>/home/mcr2/Desktop/gitManCourseFeb2022/ManipulatorsFeb2022/test_arm/src/xarm_ros/xarm_gripper/meshes/right_finger.STL</uri>
            </mesh>
          </geometry>
          <material>
            <script>
              <uri>__default__</uri>
              <name>__default__</name>
            </script>
          </material>
        </visual>
        <gravity>1</gravity>
        <velocity_decay/>
        <self_collide>0</self_collide>
        <enable_wind>0</enable_wind>
        <kinematic>0</kinematic>
      </link>
      <joint name='right_finger_joint' type='revolute'>
        <child>right_finger</child>
        <parent>right_outer_knuckle</parent>
        <axis>
          <xyz>1 0 0</xyz>
          <limit>
            <lower>0</lower>
            <upper>0.85</upper>
            <effort>50</effort>
            <velocity>2</velocity>
          </limit>
          <dynamics>
            <spring_reference>0</spring_reference>
            <spring_stiffness>0</spring_stiffness>
          </dynamics>
          <use_parent_model_frame>1</use_parent_model_frame>
        </axis>
      </joint>
      <plugin name='gazebo_ros_control' filename='libgazebo_ros_control.so'>
        <robotNamespace>/xarm</robotNamespace>
        <robotSimType>gazebo_ros_control/DefaultRobotHWSim</robotSimType>
        <legacyModeNS>1</legacyModeNS>
      </plugin>
      <plugin name='gazebo_grasp_fix' filename='libgazebo_grasp_fix.so'>
        <arm>
          <arm_name>xarm_gripper</arm_name>
          <palm_link>link7</palm_link>
          <gripper_link>left_inner_knuckle</gripper_link>
          <gripper_link>right_inner_knuckle</gripper_link>
          <gripper_link>left_finger</gripper_link>
          <gripper_link>right_finger</gripper_link>
        </arm>
        <forces_angle_tolerance>100</forces_angle_tolerance>
        <update_rate>10</update_rate>
        <grip_count_threshold>2</grip_count_threshold>
        <max_grip_count>3</max_grip_count>
        <release_tolerance>0.0198</release_tolerance>
        <disable_collisions_on_attach>0</disable_collisions_on_attach>
        <contact_topic>__default_topic__</contact_topic>
        <robotNamespace>/</robotNamespace>
      </plugin>
      <plugin name='left_finger_jointmimic_joint_plugin' filename='libroboticsgroup_upatras_gazebo_mimic_joint_plugin.so'>
        <joint>drive_joint</joint>
        <mimicJoint>left_finger_joint</mimicJoint>
        <multiplier>1.0</multiplier>
        <offset>0</offset>
        <sensitiveness>0.0</sensitiveness>
        <maxEffort>10.0</maxEffort>
        <robotNamespace>/</robotNamespace>
      </plugin>
      <plugin name='left_inner_knuckle_jointmimic_joint_plugin' filename='libroboticsgroup_upatras_gazebo_mimic_joint_plugin.so'>
        <joint>drive_joint</joint>
        <mimicJoint>left_inner_knuckle_joint</mimicJoint>
        <multiplier>1.0</multiplier>
        <offset>0</offset>
        <sensitiveness>0.0</sensitiveness>
        <maxEffort>10.0</maxEffort>
        <robotNamespace>/</robotNamespace>
      </plugin>
      <plugin name='right_outer_knuckle_jointmimic_joint_plugin' filename='libroboticsgroup_upatras_gazebo_mimic_joint_plugin.so'>
        <joint>drive_joint</joint>
        <mimicJoint>right_outer_knuckle_joint</mimicJoint>
        <multiplier>1.0</multiplier>
        <offset>0</offset>
        <sensitiveness>0.0</sensitiveness>
        <maxEffort>10.0</maxEffort>
        <robotNamespace>/</robotNamespace>
      </plugin>
      <plugin name='right_finger_jointmimic_joint_plugin' filename='libroboticsgroup_upatras_gazebo_mimic_joint_plugin.so'>
        <joint>drive_joint</joint>
        <mimicJoint>right_finger_joint</mimicJoint>
        <multiplier>1.0</multiplier>
        <offset>0</offset>
        <sensitiveness>0.0</sensitiveness>
        <maxEffort>10.0</maxEffort>
        <robotNamespace>/</robotNamespace>
      </plugin>
      <static>0</static>
      <plugin name='right_inner_knuckle_jointmimic_joint_plugin' filename='libroboticsgroup_upatras_gazebo_mimic_joint_plugin.so'>
        <joint>drive_joint</joint>
        <mimicJoint>right_inner_knuckle_joint</mimicJoint>
        <multiplier>1.0</multiplier>
        <offset>0</offset>
        <sensitiveness>0.0</sensitiveness>
        <maxEffort>10.0</maxEffort>
        <robotNamespace>/</robotNamespace>
      </plugin>
      <pose frame=''>-0.2 -0.2 1.021 0 -0 1.8</pose>
    </model>
    <state world_name='default'>
      <sim_time>482 34000000</sim_time>
      <real_time>690 439689872</real_time>
      <wall_time>1643634390 858988923</wall_time>
      <iterations>482034</iterations>
      <model name='ground_plane'>
        <pose frame=''>0 0 0 0 -0 0</pose>
        <scale>1 1 1</scale>
        <link name='link'>
          <pose frame=''>0 0 0 0 -0 0</pose>
          <velocity>0 0 0 0 -0 0</velocity>
          <acceleration>0 0 0 0 -0 0</acceleration>
          <wrench>0 0 0 0 -0 0</wrench>
        </link>
      </model>
      <model name='table'>
        <pose frame=''>-0.168818 -0.013871 0 0 -0 0</pose>
        <scale>1 1 1</scale>
        <link name='link'>
          <pose frame=''>-0.168818 -0.013871 0 0 -0 0</pose>
          <velocity>0 0 0 0 -0 0</velocity>
          <acceleration>0 0 0 0 -0 0</acceleration>
          <wrench>0 0 0 0 -0 0</wrench>
        </link>
      </model>
      <model name='xarm7'>
        <pose frame=''>-0.2 -0.199999 1.021 2e-06 -1.9e-05 1.8</pose>
        <scale>1 1 1</scale>
        <link name='left_finger'>
          <pose frame=''>-0.251037 0.165339 1.27689 -3.1273 -0.049701 1.76895</pose>
          <velocity>0.013116 -0.016719 -0.030696 -0.099082 -0.009026 -0.028884</velocity>
          <acceleration>-0 0 -0 0.001908 -0.004301 0.004826</acceleration>
          <wrench>-0 0 -0 0 -0 0</wrench>
        </link>
        <link name='left_inner_knuckle'>
          <pose frame=''>-0.299758 0.154145 1.3047 -3.1249 -0.049705 1.76896</pose>
          <velocity>0.012452 -0.012566 -0.030186 -0.098039 -0.014221 -0.029148</velocity>
          <acceleration>0 0 -0 -0.001754 0.003161 0.002785</acceleration>
          <wrench>0 0 -0 0 -0 0</wrench>
        </link>
        <link name='left_outer_knuckle'>
          <pose frame=''>-0.284698 0.15642 1.31946 -3.1249 -0.049705 1.76895</pose>
          <velocity>0.012339 -0.011549 -0.030227 -0.098452 -0.012166 -0.029044</velocity>
          <acceleration>-0 0 0 2.47178 0.269938 -1.44546</acceleration>
          <wrench>-0 0 0 0 -0 0</wrench>
        </link>
        <link name='link1'>
          <pose frame=''>-0.199997 -0.200007 1.288 1.3e-05 -1.2e-05 1.81715</pose>
          <velocity>-0 -0 -0 0 0 -0.002805</velocity>
          <acceleration>-0 -0 0 -0.601871 0.175631 -1.49775</acceleration>
          <wrench>-0 -0 0 0 -0 0</wrench>
        </link>
        <link name='link2'>
          <pose frame=''>-0.200003 -0.199983 1.28801 -1.57081 -0.341164 1.81724</pose>
          <velocity>0 -0 0 -0.028915 -0.007274 -0.002805</velocity>
          <acceleration>0 -0 0 -0.958402 0.325854 0.059005</acceleration>
          <wrench>0 -0 0 0 -0 0</wrench>
        </link>
        <link name='link3'>
          <pose frame=''>-0.176086 -0.295054 1.56411 -0.026308 -0.340143 1.89617</pose>
          <velocity>-0.002275 0.007916 0.002923 -0.030688 -0.000234 -0.023254</velocity>
          <acceleration>0 -0 -0 -1.90751 0.624583 -1.67278</acceleration>
          <wrench>0 -0 -0 0 -0 0</wrench>
        </link>
        <link name='link4'>
          <pose frame=''>-0.191906 -0.248158 1.5816 1.52235 -1.03027 1.92895</pose>
          <velocity>-0.001188 0.008821 0.00148 -0.069128 -0.012828 -0.024263</velocity>
          <acceleration>-0 -0 -0 2.75638 -0.251757 1.00495</acceleration>
          <wrench>-0 -0 -0 0 -0 0</wrench>
        </link>
        <link name='link5'>
          <pose frame=''>-0.29318 0.069731 1.472 -3.12315 -1.03078 1.85099</pose>
          <velocity>0.00793 0.003703 -0.021794 -0.071866 -0.00403 -0.029785</velocity>
          <acceleration>-0 0 0 -0.483302 -0.789658 -1.83186</acceleration>
          <wrench>-0 0 0 0 -0 0</wrench>
        </link>
        <link name='link6'>
          <pose frame=''>-0.293179 0.06973 1.47199 -1.56141 -0.050883 1.86638</pose>
          <velocity>0.00793 0.003702 -0.021794 -0.098463 -0.012144 -0.029524</velocity>
          <acceleration>0 0 0 0.505288 0.136535 2.29179</acceleration>
          <wrench>0 0 0 0 -0 0</wrench>
        </link>
        <link name='link7'>
          <pose frame=''>-0.317598 0.146794 1.37898 -3.12731 -0.049708 1.76896</pose>
          <velocity>0.011335 -0.004734 -0.029679 -0.098452 -0.012166 -0.029044</velocity>
          <acceleration>-0 0 -0 -0.035717 1.43488 1.64973</acceleration>
          <wrench>-0 0 -0 0 -0 0</wrench>
        </link>
        <link name='link_base'>
          <pose frame=''>-0.2 -0.199999 1.021 2e-06 -1.9e-05 1.8</pose>
          <velocity>0 0 0 0 -0 0</velocity>
          <acceleration>-0 -0 -0 -2.0034 -0.013509 -2.86391</acceleration>
          <wrench>-0 -0 -0 0 -0 0</wrench>
        </link>
        <link name='right_finger'>
          <pose frame=''>-0.388977 0.137539 1.2789 -3.12731 -0.049696 1.76895</pose>
          <velocity>0.012218 -0.012531 -0.029578 -0.098517 -0.011839 -0.029027</velocity>
          <acceleration>0 0 -0 -0.000151 0.000131 0.000323</acceleration>
          <wrench>0 0 -0 0 -0 0</wrench>
        </link>
        <link name='right_inner_knuckle'>
          <pose frame=''>-0.338965 0.146243 1.30527 -3.12971 -0.049705 1.76895</pose>
          <velocity>0.012216 -0.011371 -0.029885 -0.098746 -0.0107 -0.028969</velocity>
          <acceleration>-0 0 0 0.002083 -0.004083 0.003127</acceleration>
          <wrench>-0 0 0 0 -0 0</wrench>
        </link>
        <link name='right_outer_knuckle'>
          <pose frame=''>-0.353311 0.142592 1.32046 -3.12971 -0.049696 1.76895</pose>
          <velocity>0.011925 -0.009458 -0.0297 -0.09877 -0.010579 -0.028963</velocity>
          <acceleration>0 0 0 0.001634 -0.00388 0.002604</acceleration>
          <wrench>0 0 0 0 -0 0</wrench>
        </link>
      </model>
      <light name='sun'>
        <pose frame=''>0 0 10 0 -0 0</pose>
      </light>
    </state>
    <gui fullscreen='0'>
      <camera name='user_camera'>
        <pose frame=''>-5.89111 -1.374 2.49097 0 0.279643 0.332187</pose>
        <view_controller>orbit</view_controller>
        <projection_type>perspective</projection_type>
      </camera>
    </gui>
  </world>
</sdf>
